Workbook

Sheet Шаблон Медиаплана
C8: Сводные показатели:
C9: Общее количество показов | D9: =P24 -> 252176.4
C10: Общее количество кликов | D10: =Q24 -> 16600
C11: Средний CTR % | D11: =R24 -> 0.065826938
C12: Средний CPC (цена за клик) | D12: =S24 -> 0.47349376
C13: Средний % конверсии | D13: =T24 -> 0.49487952
C14: Конверсии | D14: =U24 -> 8215
C15: Цена конверсии | D15: =V24 -> 0.95678593
C16: Итого бюджет , без НДС | D16: =M24 -> 6442.62
C17: НДС 22% | D17: =N24 -> 1417.3764
C18: Итого бюджет , с НДС | D18: =O24 -> 7859.9964
P19: Прогноз, с НДС
B20: № | C20: Рекламная кампания | D20: Рекламная система | E20: Описание | F20: Гео | G20: Формат | H20: Вид ротации | I20: Период | K20: Единица измерения стоимости размещения | L20: Стоимость CPC по прогнозатору (без НДС) | M20: Итого стоимость по прайс-листу, без НДС | N20: НДС, 22% | O20: Итоговая стоимость с НДС (бюджет) | P20: Общее количество показов | Q20: Клики | R20: CTR | S20: CPC | T20: % конверсии | U20: Кол-во конверсий | V20: Цена конверсии
B21: 1 | C21: Контекстная реклама в Yandex.Direct. Поиск | D21: Яндекс.Директ Поиск | E21: Поиск по горячим запросам: пользователь уже ищет розы и саженцы; ведём на релевантные страницы каталога. | F21: Россия | G21: Текстовые объявления | H21: динамика | I21: 1 | J21: мес | K21: клик | L21: 6 | M21: 3000 | N21: =M21*0.22 -> 660 | O21: =M21+N21 -> 3660 | P21: =Q21/R21 -> 21186.441 | Q21: =O21/S21 -> 500 | R21: 0.0236 | S21: =L21*1.22 -> 7.32 | T21: 0.05 | U21: =Q21*T21 -> 25 | V21: =O21/U21 -> 146.4
B22: =B21+1 -> 2 | C22: Таргетированная реклама во «ВКонтакте» | D22: ВКонтакте | E22: Сегмент «После пересорта»: проверяем доверие и переходы на сайт. | F22: Россия | G22: ПромоCTA/Карусель/Сторис | H22: динамика | I22: 7 | J22: дней | K22: клик | L22: 0.21 | M22: 1721.31 | N22: =M22*0.22 -> 378.6882 | O22: =M22+N22 -> 2099.9982 | P22: =Q22/R22 -> 115494.98 | Q22: 8050 | R22: 0.0697 | S22: =O23/Q23 -> 0.26086934 | T22: 1 | U22: =Q22*T22 -> 8050 | V22: =O22/U22 -> 0.26086934
B23: =B22+1 -> 3 | C23: Таргетированная реклама во «ВКонтакте» | D23: ВКонтакте | E23: Сегмент «Новичок»: мягкий вход через сообщение и консультацию. | F23: Россия | G23: ПромоCTA/Карусель/Сторис | H23: динамика | I23: 7 | J23: дней | K23: клик | L23: =M23/8050 -> 0.21382733 | M23: 1721.31 | N23: =M23*0.22 -> 378.6882 | O23: =M23+N23 -> 2099.9982 | P23: =Q23/R23 -> 115494.98 | Q23: =M23/L23 -> 8050 | R23: 0.0697 | S23: =L23*1.22 -> 0.26086934 | T23: =140/Q23 -> 0.017391304 | U23: =Q23*T23 -> 140 | V23: =O23/U23 -> 14.999987
C24: Итого: | L24: =M24/Q24 -> 0.38810964 | M24: =SUM(M21:M23) -> 6442.62 | N24: =SUM(N21:N23) -> 1417.3764 | O24: =SUM(O21:O23) -> 7859.9964 | P24: =SUM(P21:P23) -> 252176.4 | Q24: =SUM(Q21:Q23) -> 16600 | R24: =Q24/P24 -> 0.065826938 | S24: =O24/Q24 -> 0.47349376 | T24: =U24/Q24 -> 0.49487952 | U24: =SUM(U21:U23) -> 8215 | V24: =O24/U24 -> 0.95678593
K27: Стоимость и услуги | M27: без НДС | N27: НДС | O27: с НДС
K28: Рекламный бюджет: | M28: =M24 -> 6442.62 | N28: =M28*0.22 -> 1417.3764 | O28: =M28+N28 -> 7859.9964
K29: Аналитика, настройка и сопровождение | M29: =O29/1.22 -> 0 | N29: =M29*0.22 -> 0
K30: Итого: | M30: =SUM(M28:M29) -> 6442.62 | N30: =M30*0.22 -> 1417.3764 | O30: =M30+N30 -> 7859.9964
K33: Обоснование бюджета:
K34: Бюджет рассчитан как первый тестовый запуск. На старте мы не расходуем весь рекламный фонд сразу: сначала проверяем три связки — поиск в Яндекс Директе, VK-клики для сегмента «После пересорта» и VK-сообщения для сегмента «Новичок». Цель теста — получить первые рабочие данные: CTR, CPC, цену результата и качество целевых действий. После этого бюджет масштабируется не «по плану на бумаге», а на те связки, которые подтвердили себя цифрами.

Sheet Прогноз и тест
C2: Тамара Розы
C3: Единый медиаплан: от брифа к прогнозу, тесту и масштабированию
C4: Россия · Яндекс Директ · VK Реклама
C6: Разбор брифа: что берём в работу
C7: 1. Бюджет
C8: Из учебного задания берём только рекламный бюджет — 550 000 ₽. Старые 5 000 ₽ ежемесячно и 50 000 ₽ летом из брифа не используем. В задании 550 000 ₽ указаны именно как рекламный бюджет.
C10: 2. Главная цель
C11: В брифе три разноуровневые цели: заказы на сайте, рост групп и общая видимость сайта. Единственная цель с цифрой — 30 заказов в день на сайте. Её берём как главную бизнес-цель медиаплана. Рост сообщества оставляем второстепенным показателем: в брифе нет ни целевого количества подписчиков, ни срока.
C13: 3. География
C14: В работе фиксируем: Россия. На сайте подтверждены отправки через СДЭК и Почту России; питомник находится в Пскове.
C16: 4. Продукт и ассортимент
C17: На сайте расходятся цифры ассортимента: главная говорит о более чем 1 300 сортах, раздел «О питомнике» — о 569, FAQ — о более чем 1 400, статья — о более чем 1 500. Не выносим ни единой фиксированную цифры, пока сайт не приведёт их к одному значению.
... C52: 2. ФОРМУЛА ТЕСТОВОГО БЮДЖЕТА
C54: Полная карта контекстных групп для выбора теста | K54: Сводные показатели для шаблона | P54: VK Реклама: формулы и решения по 2 сегментам
C55: Кампания | D55: Регион | E55: Показы | F55: Клики | G55: CTR, % | H55: Ср. цена клика, руб. | I55: Бюджет | K55: Показатель | L55: Обозн. | M55: Формула словами | N55: Значение | P55: Показатель | Q55: Обозн. | R55: Формула | S55: Новичок | T55: После пересорта | U55: Итого / среднее
C56: Поиск - Английская роза | D56: Россия | H56: =INDEX(Проверка_CPC!$E:$E,MATCH("Английская роза.xlsx",Проверка_CPC!$A:$A,0)) -> 8.54 | K56: Общее количество показов | L56: Imp | M56: Итог показов | N56: =E76 -> 21196.974 | P56: Бюджет в день | Q56: Budget | R56: из VK-кабинета | S56: =300 -> 300 | T56: =300 -> 300 | U56: =S56+T56 -> 600
C57: Поиск - Бренд | D57: Россия | H57: =INDEX(Проверка_CPC!$E:$E,MATCH("Поиск Бренд.xlsx",Проверка_CPC!$A:$A,0)) -> 6.1 | K57: Общее количество кликов | L57: Clicks | M57: Итог кликов | N57: =TEXT(F76,"0") -> 500 | P57: Период теста | S57: 7 | T57: 7
C58: Поиск - Исторические розы | D58: Россия | H58: =INDEX(Проверка_CPC!$E:$E,MATCH("Исторические розы.xlsx",Проверка_CPC!$A:$A,0)) -> 8.54 | K58: Средний CTR | L58: CTR | M58: Клики ÷ показы | N58: =F76/E76 -> 0.023588273 | P58: Аудитория | Q58: Audience | R58: из VK-кабинета | S58: =278000 -> 278000 | T58: =278000 -> 278000 | U58: не суммируем
C59: Поиск - Канадские розы | D59: Россия | H59: =INDEX(Проверка_CPC!$E:$E,MATCH("канадские.xlsx",Проверка_CPC!$A:$A,0)) -> 8.54 | K59: Средний CPC | L59: CPC | M59: Бюджет ÷ клики | N59: =I76/F76 -> 7.32 | P59: Охват | Q59: Reach | R59: (min + max) ÷ 2 | S59: =(11000+16000)/2*7 -> 94500 | T59: =(11000+16000)/2*7 -> 94500 | U59: =S59+T59 -> 189000
C60: Поиск - Миниатюрные розы | D60: Россия | H60: =INDEX(Проверка_CPC!$E:$E,MATCH("Миниатюрные розы.xlsx",Проверка_CPC!$A:$A,0)) -> 7.32 | K60: Средний % конверсии | L60: CR | M60: Заказы ÷ клики | N60: =25/500 -> 0.05 | P60: Показы | Q60: Imp | R60: (min + max) ÷ 2 | S60: =(14000+19000)/2*7 -> 115500 | T60: =(14000+19000)/2*7 -> 115500 | U60: =S60+T60 -> 231000
C61: Поиск - Мускусные розы | D61: Россия | H61: =INDEX(Проверка_CPC!$E:$E,MATCH("Мускусная роза.xlsx",Проверка_CPC!$A:$A,0)) -> 7.32 | K61: Конверсии | L61: Conv | M61: Клики × CR | N61: =N57*N60 -> 25 | P61: Клики | Q61: Clicks | R61: (min + max) ÷ 2 | S61: =(1000+1300)/2*7 -> 8050 | T61: =(1000+1300)/2*7 -> 8050 | U61: =S61+T61 -> 16100
C62: Поиск - Парковые розы | D62: Россия | H62: =INDEX(Проверка_CPC!$E:$E,MATCH("Парковые розы.xlsx",Проверка_CPC!$A:$A,0)) -> 9.76 | K62: Цена конверсии | L62: CPA | M62: Бюджет ÷ конверсии | N62: =I76/N61 -> 146.4 | P62: CTR | Q62: CTR | R62: клики ÷ показы | S62: =S61/S60 -> 0.06969697 | T62: =T61/T60 -> 0.06969697 | U62: =U61/U60 -> 0.06969697
C63: Поиск - Плетистые розы | D63: Россия | E63: =F63/G63 -> 2936.5739 | F63: 100 | G63: =INDEX(Прогноз_Direct_85!$F:$F,MATCH("Плетистые.xls",Прогноз_Direct_85!$A:$A,0)) -> 0.034053289 | H63: =INDEX(Проверка_CPC!$E:$E,MATCH("Плетистая.xlsx",Проверка_CPC!$A:$A,0)) -> 4.88 | I63: =F63*H63 -> 488 | K63: Итого бюджет без НДС | L63: Net | M63: Бюджет с НДС ÷ 1,22 | N63: =I76/1.22 -> 3000 | P63: Частота | Q63: Freq. | R63: показы ÷ охват | S63: =S60/S59 -> 1.2222222 | T63: =T60/T59 -> 1.2222222 | U63: =U60/U59 -> 1.2222222
C64: Поиск - Почвопокровные розы | D64: Россия | H64: =INDEX(Проверка_CPC!$E:$E,MATCH("Почвопокровные.xlsx",Проверка_CPC!$A:$A,0)) -> 8.54 | K64: НДС 22% | L64: VAT | M64: Бюджет с НДС − бюджет без НДС | N64: =I76-(I76/1.22) -> 660 | P64: Минимум действий | Q64: Test result | R64: 20 действий на сегмент | S64: =20 -> 20 | T64: =20 -> 20 | U64: =S64+T64 -> 40
C65: Поиск - Розы Остина | D65: Россия | H65: =INDEX(Проверка_CPC!$E:$E,MATCH("Розы Остина.xlsx",Проверка_CPC!$A:$A,0)) -> 8.54 | K65: Итого бюджет с НДС | L65: Gross | M65: Итог бюджета из таблицы контекста | N65: =I76 -> 3660 | P65: Конверсии / результат | Q65: Result | R65: целевое действие сегмента | S65: =S64*7 -> 140 | T65: =T61 -> 8050 | U65: не сводим
C66: Поиск - Саженцы роз | D66: Россия | H66: =INDEX(Проверка_CPC!$E:$E,MATCH("Саженцы.xlsx",Проверка_CPC!$A:$A,0)) -> 10.98 | P66: Средний % конверсии | Q66: CR | R66: результат ÷ клики | S66: =S65/S61 -> 0.017391304 | T66: =T65/T61 -> 1 | U66: не сводим
C67: Поиск - Флорибунда | D67: Россия | E67: =F67/G67 -> 5198.4623 | F67: 100 | G67: =INDEX(Прогноз_Direct_85!$F:$F,MATCH("Флорибунда.xls",Прогноз_Direct_85!$A:$A,0)) -> 0.019236458 | H67: =INDEX(Проверка_CPC!$E:$E,MATCH("Флорибунда.xlsx",Проверка_CPC!$A:$A,0)) -> 7.32 | I67: =F67*H67 -> 732 | P67: Средний CPC | Q67: CPC | R67: бюджет ÷ клики | S67: =S70/S65 -> 15 | T67: =T70/T65 -> 0.26086957 | U67: =U56/U61 -> 0.037267081
C68: Поиск - Чайно-гибридные розы | D68: Россия | E68: =F68/G68 -> 5631.8436 | F68: 100 | G68: =INDEX(Прогноз_Direct_85!$F:$F,MATCH("Чайно-гибридные.xls",Прогноз_Direct_85!$A:$A,0)) -> 0.017756175 | H68: =INDEX(Проверка_CPC!$E:$E,MATCH("чайно гибридная.xlsx",Проверка_CPC!$A:$A,0)) -> 4.88 | I68: =F68*H68 -> 488 | P68: Цена результата | Q68: CPA / CPR | R68: бюджет ÷ результат | S68: =S70/S65 -> 15 | T68: =T70/T65 -> 0.26086957 | U68: не сводим
C69: Поиск - Шрабы | D69: Россия | H69: =INDEX(Проверка_CPC!$E:$E,MATCH("Шрабы.xlsx",Проверка_CPC!$A:$A,0)) -> 7.32 | P69: НДС 22% | Q69: VAT | S69: 378.69 | T69: 378.69 | U69: 757.38
C70: Поиск - Японские розы | D70: Россия | H70: =INDEX(Проверка_CPC!$E:$E,MATCH("Японские розы.xlsx",Проверка_CPC!$A:$A,0)) -> 8.54 | P70: Бюджет с НДС | Q70: Gross | S70: 2100 | T70: 2100 | U70: 4200
C71: РСЯ - Бренд | D71: Россия | H71: =INDEX(Проверка_CPC!$E:$E,MATCH("РСЯ Тамара Розы.xlsx",Проверка_CPC!$A:$A,0)) -> 3.66 | P71: Бюджет без НДС | Q71: Net | S71: 1721.31 | T71: 1721.31 | U71: 3442.62
C73: РСЯ - Общие розы | D73: Россия | H73: =INDEX(Проверка_CPC!$E:$E,MATCH("РСЯ общие розы.xlsx",Проверка_CPC!$A:$A,0)) -> 10.98 | P73: Источник: домашки VK + учебные материалы. Новичок: цель «Отправка сообщения», аудитория ~278 тыс.; После пересорта: цель «Клики по рекламе», аудитория ~278 тыс. Бюджет: 300 ₽/день на сегмент; планирование бюджета VK — от стоимости не менее 20 целевых действий.
C74: РСЯ - Популярные категории | D74: Россия | E74: =F74/G74 -> 4925.6866 | F74: 100 | G74: =INDEX(Прогноз_Direct_85!$F:$F,MATCH("РСЯ-популярные категории.xls",Прогноз_Direct_85!$A:$A,0)) -> 0.020301738 | H74: =INDEX(Проверка_CPC!$E:$E,MATCH("РСЯ Популярные категории.xlsx",Проверка_CPC!$A:$A,0)) -> 10.98 | I74: =F74*H74 -> 1098
C75: РСЯ - Устойчивые / зимостойкие | D75: Россия | E75: =F75/G75 -> 2504.4076 | F75: 100 | G75: =INDEX(Прогноз_Direct_85!$F:$F,MATCH("РСЯ-зимостойкие.xls",Прогноз_Direct_85!$A:$A,0)) -> 0.039929603 | H75: =INDEX(Проверка_CPC!$E:$E,MATCH("РСЯ Устойчивые_зимостойкие.xlsx",Проверка_CPC!$A:$A,0)) -> 8.54 | I75: =F75*H75 -> 854
C76: Итого Яндекс | E76: =SUM(E56:E75) -> 21196.974 | F76: =SUM(F56:F75) -> 500 | G76: =F76/E76 -> 0.023588273 | H76: =I76/F76 -> 7.32 | I76: =SUM(I56:I75) -> 3660
C78: CPC в столбце «Ср. CPC» не введён вручную: каждая ячейка берёт значение из внутреннего листа «Проверка_CPC» — результата запроса Power Query «CPC_выгрузки_Яндекс». В каждой строке источника сохранено имя исходного файла. «Прогноз бюджета» рассчитывает ставки, показы и клики по выбранным регионам и ключевым фразам и даёт выгрузку XLS
C80: Вывод: на первом тесте в Директе не дробим бюджет на пятнадцать направлений и не ждём 25 заказов от каждого. Сначала проверяем 3-4 самых ёмких коммерческих кластера до 100 кликов на кластер. После этого у нас будет свой CPC, CTR. Победителей переводим в отдельную кампанию на конверсии.
C82: 3. Берём в тест по поиску
C83: Группа | D83: Почему берём | G83: CPC для медиаплана | H83: Минимум на 100 кликов
C84: Плетистые розы | D84: Сильная категория, большой спрос, самый дешёвый CPC среди крупных групп | G84: =H63 -> 4.88 | H84: =G84*100 -> 488
...

Sheet Проверка_CPC
A1: Power Query — CPC_выгрузки_Яндекс
A2: Загруженный в книгу результат запроса. В столбце E — CPC, который используется в дорожной карте.
A4: Файл | B4: Первая_фраза_для_проверки | C4: CPC_точный_из_столбца_I | D4: CPC_округлённый | E4: CPC_для_медиаплана_с_1_22
A5: Английская роза.xlsx | B5: английская роза | C5: 6.6391304 | D5: 7 | E5: 8.54
A6: Исторические розы.xlsx | B6: луиз одье роза | C6: 7.0888889 | D6: 7 | E6: 8.54
A7: канадские.xlsx | B7: канадская роза александр маккензи | C7: 6.58 | D7: 7 | E7: 8.54
A8: Миниатюрные розы.xlsx | B8: миниатюрный саженец роз | C8: 6.0555556 | D8: 6 | E8: 7.32
A9: Мускусная роза.xlsx | B9: мускусная роза белая | C9: 6.2214286 | D9: 6 | E9: 7.32
A10: Парковые розы.xlsx | B10: купить парковую розу | C10: 7.71875 | D10: 8 | E10: 9.76
A11: Плетистая.xlsx | B11: желтые плетистые розы | C11: 3.6 | D11: 4 | E11: 4.88
A12: Поиск Бренд.xlsx | B12: магазин тамара розы | C12: 4.7 | D12: 5 | E12: 6.1
A13: Почвопокровные.xlsx | B13: зимостойкие почвопокровные розы | C13: 7.392 | D13: 7 | E13: 8.54
A14: Розы Остина.xlsx | B14: английская роза дэвида остина | C14: 6.8217391 | D14: 7 | E14: 8.54
A15: РСЯ общие розы.xlsx | B15: интернет магазин саженцев роз | C15: 9.4833333 | D15: 9 | E15: 10.98
A16: РСЯ Популярные категории.xlsx | B16: плетистые розы | C16: 8.5 | D16: 9 | E16: 10.98
... A23: Японские розы.xlsx | B23: белая японская роза | C23: 6.5086957 | D23: 7 | E23: 8.54

Sheet Прогноз_Direct_85
A1: Power Query — Прогноз_Direct_85
A2: Сводная таблица по 5 выгрузкам Яндекс Директа: объём трафика 85. В основной лист передаётся CTR_85; клики в тестовом расчёте остаются 100 на группу.
A4: Файл | B4: Строка_медиаплана | C4: Группа_в_медиаплане | D4: Показы_85 | E4: Клики_85 | F4: CTR_85 | G4: CPC_85_без_НДС | H4: Бюджет_85_без_НДС
A5: Плетистые.xls | B5: 63 | C5: Поиск - Плетистые розы | D5: 81255 | E5: 2767 | F5: 0.034053289 | G5: 8.6833394 | H5: 24026.8
A6: Флорибунда.xls | B6: 67 | C6: Поиск - Флорибунда | D6: 111559 | E6: 2146 | F6: 0.019236458 | G6: 7.9497204 | H6: 17060.1
A7: Чайно-гибридные.xls | B7: 68 | C7: Поиск - Чайно-гибридные розы | D7: 70567 | E7: 1253 | F7: 0.017756175 | G7: 8.06249 | H7: 10102.3
A8: РСЯ-популярные категории.xls | B8: 73 | C8: РСЯ - Популярные категории | D8: 182940 | E8: 3714 | F8: 0.020301738 | G8: 12.0965 | H8: 44926.4
A9: РСЯ-зимостойкие.xls | B9: 74 | C9: РСЯ - Устойчивые / зимостойкие | D9: 52843 | E9: 2110 | F9: 0.039929603 | G9: 10.291896 | H9: 21715.9
A10: Итого / среднее | D10: =SUM(D5:D9) -> 499164 | E10: =SUM(E5:E9) -> 11990 | F10: =E10/D10 -> 0.024020162 | G10: =H10/E10 -> 9.8274812 | H10: =SUM(H5:H9) -> 117831.5
A13: Детализация по фразам из пяти выгрузок
A14: Файл | B14: Фраза | C14: Запросы | D14: Объем_трафика | E14: Показы_85 | F14: Клики_85 | G14: CPC_85_без_НДС | H14: Бюджет_85_без_НДС
A15: Плетистые.xls | B15: желтые плетистые розы | C15: 3086 | D15: 85 | E15: 2420 | F15: 41 | G15: 16.5 | H15: 676.5
A16: Плетистые.xls | B16: зимостойкие плетистые розы | C16: 2176 | D16: 85 | E16: 1655 | F16: 97 | G16: 7.4 | H16: 717.8
A17: Плетистые.xls | B17: индиголетта роза плетистая | C17: 2624 | D17: 85 | E17: 2144 | F17: 73 | G17: 4.5 | H17: 328.5
A18: Плетистые.xls | B18: канадские плетистые розы | C18: 1428 | D18: 85 | E18: 1235 | F18: 41 | G18: 13.9 | H18: 569.9
A19: Плетистые.xls | B19: морозостойкие плетистые розы | C19: 1868 | D19: 85 | E19: 1375 | F19: 65 | G19: 9.4 | H19: 611
A20: Плетистые.xls | B20: плетистая роза без шипов | C20: 893 | D20: 85 | E20: 793 | F20: 24 | G20: 14.2 | H20: 340.8
A21: Плетистые.xls | B21: плетистая роза даун | C21: 662 | D21: 85 | E21: 505 | F21: 21 | G21: 4 | H21: 84
A22: Плетистые.xls | B22: плетистая роза де ронсар | C22: 4632 | D22: 85 | E22: 48 | F22: 3 | G22: 2.5 | H22: 7.5
A23: Плетистые.xls | B23: плетистая роза жуан | C23: 1078 | D23: 85 | E23: 904 | F23: 17 | G23: 7.6 | H23: 129.2
A24: Плетистые.xls | B24: плетистая роза клаймбер | C24: 1189 | D24: 85 | E24: 924 | F24: 18 | G24: 11.8 | H24: 212.4
A25: Плетистые.xls | B25: плетистая роза купить саженцы | C25: 2020 | D25: 85 | E25: 1596 | F25: 158 | G25: 15.9 | H25: 2512.2
A26: Плетистые.xls | B26: плетистая роза леди | C26: 511 | D26: 85 | E26: 392 | F26: 18 | G26: 9.4 | H26: 169.2
... A188: РСЯ-зимостойкие.xls | B188: морозостойкие розы | C188: 7477 | D188: 85 | E188: 6852 | F188: 337 | G188: 9.8 | H188: 3302.6
